Workbook

Sheet README
A1: D4 PIPELINE & FORECAST DASHBOARD
A2: Company | B2: Strata Sense is fictional; all data synthetic (MBA capstone).
A3: How to use | B3: Dashboard: pick a dimension and fiscal year in the yellow cells; the performance table and chart update. Blue = input; black = formula.
A4: Sheets | B4: Dashboard · Coverage · Backtest · Holdout · Perf_data · Hygiene · Scenarios · Governance
A5: Sources | B5: DR1 CRM (cleaned in D1), pipeline snapshots (12 quarter starts + the 1 Apr 2026 hold-out), DR1 forecast history, DR3 bookings. Code: d4_prep.py, d4_methods.py, d4_final.py, d4_views.py.
A6: Hold-out | B6: Q1 FY27 forecast locked before any outcome was seen: p10 ₹6.11 cr, p50 ₹8.71 cr, p90 ₹10.74 cr (SHA-256 ba5b63adaffbe366…).

Sheet Perf_data
A1: Performance data (qualified closed deals, FY24–FY26)
A2: Long table feeding the Dashboard selector
A4: dimension | B4: value | C4: fy | D4: qualified_deals | E4: win_rate | F4: avg_won_deal_lakh | G4: avg_cycle_days | H4: velocity_lakh_per_day | I4: key
A5: Segment | B5: Discrete manufacturing | C5: FY24 | D5: 161 | E5: 0.25465839 | F5: 35.224146 | G5: 197.07317 | H5: 7.3281918 | I5: Segment|Discrete manufacturing|FY24
A6: Segment | B6: Discrete manufacturing | C6: FY25 | D6: 160 | E6: 0.2 | F6: 45.60125 | G6: 204.96875 | H6: 7.1193292 | I6: Segment|Discrete manufacturing|FY25
A7: Segment | B7: Discrete manufacturing | C7: FY26 | D7: 178 | E7: 0.1741573 | F7: 46.508387 | G7: 270.22581 | H7: 5.3353898 | I7: Segment|Discrete manufacturing|FY26
A8: Segment | B8: Energy & utilities | C8: FY24 | D8: 62 | E8: 0.25806452 | F8: 46.4975 | G8: 176.125 | H8: 4.2240454 | I8: Segment|Energy & utilities|FY24
A9: Segment | B9: Energy & utilities | C9: FY25 | D9: 63 | E9: 0.20634921 | F9: 52.859231 | G9: 252.46154 | H9: 2.72188 | I9: Segment|Energy & utilities|FY25
A10: Segment | B10: Energy & utilities | C10: FY26 | D10: 56 | E10: 0.23214286 | F10: 81.316154 | G10: 257.84615 | H10: 4.0997703 | I10: Segment|Energy & utilities|FY26
A11: Segment | B11: Other | C11: FY24 | D11: 39 | E11: 0.1025641 | F11: 15.91 | G11: 125 | H11: 0.50912 | I11: Segment|Other|FY24
A12: Segment | B12: Other | C12: FY25 | D12: 41 | E12: 0.048780488 | F12: 43.495 | G12: 177 | H12: 0.49146893 | I12: Segment|Other|FY25
A13: Segment | B13: Other | C13: FY26 | D13: 80 | E13: 0.075 | F13: 43.98 | G13: 230.33333 | H13: 1.145644 | I13: Segment|Other|FY26
A14: Segment | B14: Process industries | C14: FY24 | D14: 148 | E14: 0.25 | F14: 51.574054 | G14: 190.43243 | H14: 10.020562 | I14: Segment|Process industries|FY24
A15: Segment | B15: Process industries | C15: FY25 | D15: 112 | E15: 0.24107143 | F15: 61.724074 | G15: 227.55556 | H15: 7.3237061 | I15: Segment|Process industries|FY25
A16: Segment | B16: Process industries | C16: FY26 | D16: 118 | E16: 0.19491525 | F16: 58.14087 | G16: 204.30435 | H16: 6.545333 | I16: Segment|Process industries|FY26
... A76: Account tier (D2) | B76: 3 Low-touch | C76: FY26 | D76: 203 | E76: 0.11330049 | F76: 27.968261 | G76: 247.47826 | H76: 2.599299 | I76: Account tier (D2)|3 Low-touch|FY26

Sheet Lists
A1: Segment | C1: Segment | D1: Lead source | E1: Competitor (recorded) | F1: Rep tenure | G1: Region | H1: Account tier (D2)
A2: Lead source | C2: Discrete manufacturing | D2: AE self-sourced | E2: Bharat Machine Intelligence | F2: 9-24 months | G2: India | H2: 1 Strategic
A3: Competitor (recorded) | C3: Energy & utilities | D3: Customer referral | E3: Helix Automation | F3: <9 months | G3: Middle East | H3: 2 Scaled
A4: Rep tenure | C4: Other | D4: Event | E4: None / unknown | F4: >24 months | G4: SEA | H4: 3 Low-touch
A5: Region | C5: Process industries | D5: Partner | E5: TrueSense AI | F5: Reassigned deal
A6: Account tier (D2) | D6: SDR / Marketing
D7: Unknown

Sheet Coverage
A1: Required vs reported coverage by quarter
A2: Required = 1 ÷ trailing-4-quarter in-quarter conversion of reported pipeline
A3: quarter | B3: quota_cr | C3: reported_pipeline_in_quarter_cr | D3: commit_call_m1_cr | E3: coverage_reported | F3: inq_conversion | G3: actual_clean_cr | H3: coverage_required | I3: attainment
A4: Q1 FY24 | B4: 14.39 | C4: 28.21 | D4: 13.51 | E4: 1.9603892 | F4: 0.44761078 | G4: 12.6271 | I4: 0.87749131
A5: Q2 FY24 | B5: 15.16 | C5: 26.59 | D5: 9.31 | E5: 1.7539578 | F5: 0.34846559 | G5: 9.2657 | I5: 0.61119393
A6: Q3 FY24 | B6: 15.63 | C6: 37.16 | D6: 10.79 | E6: 2.3774792 | F6: 0.27248654 | G6: 10.1256 | H6: 2.5123218 | I6: 0.64783109
A7: Q4 FY24 | B7: 16.11 | C7: 46.25 | D7: 10.95 | E7: 2.8708876 | F7: 0.20717622 | G7: 9.5819 | H7: 2.807509 | I7: 0.59477964
A8: Q1 FY25 | B8: 16.33 | C8: 45.61 | D8: 11.65 | E8: 2.793019 | F8: 0.27371191 | G8: 12.484 | H8: 3.1354373 | I8: 0.76448255
A9: Q2 FY25 | B9: 16.49 | C9: 43.63 | D9: 15.52 | E9: 2.645846 | F9: 0.22138895 | G9: 9.6592 | H9: 3.6302903 | I9: 0.58576107
A10: Q3 FY25 | B10: 16.81 | C10: 39.39 | D10: 7.61 | E10: 2.3432481 | F10: 0.18211475 | G10: 7.1735 | H10: 4.103559 | I10: 0.42674004
A11: Q4 FY25 | B11: 17.16 | C11: 50.7 | D11: 10.09 | E11: 2.9545455 | F11: 0.19098225 | G11: 9.6828 | H11: 4.5228822 | I11: 0.56426573
A12: Q1 FY26 | B12: 17.16 | C12: 58.24 | D12: 15.74 | E12: 3.3939394 | F12: 0.22721497 | G12: 13.233 | H12: 4.6072447 | I12: 0.77115385
A13: Q2 FY26 | B13: 17.29 | C13: 56.44 | D13: 15.87 | E13: 3.2643146 | F13: 0.20409639 | G13: 11.5192 | H13: 4.8679512 | I13: 0.66623482
A14: Q3 FY26 | B14: 17.3 | C14: 55.62 | D14: 10.72 | E14: 3.2150289 | F14: 0.13837828 | G14: 7.6966 | H14: 4.9725988 | I14: 0.44489017
A15: Q4 FY26 | B15: 17.32 | C15: 59.08 | D15: 11.93 | E15: 3.4110855 | F15: 0.14473764 | G15: 8.5511 | H15: 5.258509 | I15: 0.49371247
A16: Q1 FY27 | B16: 17.15 | C16: 60.04 | E16: 3.5008746 | H16: 5.5988903

Sheet Dashboard
A1: Pipeline & forecast dashboard
A2: Strata Sense (fictional) · as of 1 Apr 2026 · ₹ crore unless marked
A4: FY26 bookings (clean) | B4: FY26 win rate | C4: Reported coverage Q1 FY27 | D4: Required coverage Q1 FY27 | E4: FY26 commit miss (MAPE) | F4: Hold-out p50 (locked)
A5: =SUM(Coverage!G12:G15) -> 40.9999 | B5: 0.169 | C5: =Coverage!E16 -> 3.5008746 | D5: =Coverage!H16 -> 5.5988903 | E5: =Backtest!C24 -> 0.33877885 | F5: =Holdout!B6 -> 8.71
A8: PERFORMANCE VIEW
A9: Dimension | B9: Rep tenure
A10: Fiscal year | B10: FY26
A12: Value | B12: Qualified deals | C12: Win rate | D12: Avg won deal (lakh) | E12: Avg cycle (days) | F12: Velocity (lakh/day)
A13: =IFERROR(IF(INDEX(Lists!$C$2:$Z$2,MATCH($B$9,Lists!$C$1:$Z$1,0))=0,"",INDEX(Lists!$C$2:$Z$2,MATCH($B$9,Lists!$C$1:$Z$1,0))),"") -> 9-24 months | B13: =IFERROR(INDEX(Perf_data!$D$5:$D$76,MATCH($B$9&"|"&$A13&"|"&$B$10,Perf_data!$I$5:$I$76,0)),"") -> 71 | C13: =IFERROR(INDEX(Perf_data!$E$5:$E$76,MATCH($B$9&"|"&$A13&"|"&$B$10,Perf_data!$I$5:$I$76,0)),"") -> 0.12676056 | D13: =IFERROR(INDEX(Perf_data!$F$5:$F$76,MATCH($B$9&"|"&$A13&"|"&$B$10,Perf_data!$I$5:$I$76,0)),"") -> 66.252222 | E13: =IFERROR(INDEX(Perf_data!$G$5:$G$76,MATCH($B$9&"|"&$A13&"|"&$B$10,Perf_data!$I$5:$I$76,0)),"") -> 211.77778 | F13: =IFERROR(INDEX(Perf_data!$H$5:$H$76,MATCH($B$9&"|"&$A13&"|"&$B$10,Perf_data!$I$5:$I$76,0)),"") -> 2.8155456
A14: =IFERROR(IF(INDEX(Lists!$C$3:$Z$3,MATCH($B$9,Lists!$C$1:$Z$1,0))=0,"",INDEX(Lists!$C$3:$Z$3,MATCH($B$9,Lists!$C$1:$Z$1,0))),"") -> <9 months | B14: =IFERROR(INDEX(Perf_data!$D$5:$D$76,MATCH($B$9&"|"&$A14&"|"&$B$10,Perf_data!$I$5:$I$76,0)),"") -> 65 | C14: =IFERROR(INDEX(Perf_data!$E$5:$E$76,MATCH($B$9&"|"&$A14&"|"&$B$10,Perf_data!$I$5:$I$76,0)),"") -> 0.092307692 | D14: =IFERROR(INDEX(Perf_data!$F$5:$F$76,MATCH($B$9&"|"&$A14&"|"&$B$10,Perf_data!$I$5:$I$76,0)),"") -> 88.515 | E14: =IFERROR(INDEX(Perf_data!$G$5:$G$76,MATCH($B$9&"|"&$A14&"|"&$B$10,Perf_data!$I$5:$I$76,0)),"") -> 245.16667 | F14: =IFERROR(INDEX(Perf_data!$H$5:$H$76,MATCH($B$9&"|"&$A14&"|"&$B$10,Perf_data!$I$5:$I$76,0)),"") -> 2.1662407
A15: =IFERROR(IF(INDEX(Lists!$C$4:$Z$4,MATCH($B$9,Lists!$C$1:$Z$1,0))=0,"",INDEX(Lists!$C$4:$Z$4,MATCH($B$9,Lists!$C$1:$Z$1,0))),"") -> >24 months | B15: =IFERROR(INDEX(Perf_data!$D$5:$D$76,MATCH($B$9&"|"&$A15&"|"&$B$10,Perf_data!$I$5:$I$76,0)),"") -> 250 | C15: =IFERROR(INDEX(Perf_data!$E$5:$E$76,MATCH($B$9&"|"&$A15&"|"&$B$10,Perf_data!$I$5:$I$76,0)),"") -> 0.192 | D15: =IFERROR(INDEX(Perf_data!$F$5:$F$76,MATCH($B$9&"|"&$A15&"|"&$B$10,Perf_data!$I$5:$I$76,0)),"") -> 49.470208 | E15: =IFERROR(INDEX(Perf_data!$G$5:$G$76,MATCH($B$9&"|"&$A15&"|"&$B$10,Perf_data!$I$5:$I$76,0)),"") -> 244 | F15: =IFERROR(INDEX(Perf_data!$H$5:$H$76,MATCH($B$9&"|"&$A15&"|"&$B$10,Perf_data!$I$5:$I$76,0)),"") -> 9.7318443
A16: =IFERROR(IF(INDEX(Lists!$C$5:$Z$5,MATCH($B$9,Lists!$C$1:$Z$1,0))=0,"",INDEX(Lists!$C$5:$Z$5,MATCH($B$9,Lists!$C$1:$Z$1,0))),"") -> Reassigned deal | B16: =IFERROR(INDEX(Perf_data!$D$5:$D$76,MATCH($B$9&"|"&$A16&"|"&$B$10,Perf_data!$I$5:$I$76,0)),"") -> 46 | C16: =IFERROR(INDEX(Perf_data!$E$5:$E$76,MATCH($B$9&"|"&$A16&"|"&$B$10,Perf_data!$I$5:$I$76,0)),"") -> 0.2173913 | D16: =IFERROR(INDEX(Perf_data!$F$5:$F$76,MATCH($B$9&"|"&$A16&"|"&$B$10,Perf_data!$I$5:$I$76,0)),"") -> 59.806 | E16: =IFERROR(INDEX(Perf_data!$G$5:$G$76,MATCH($B$9&"|"&$A16&"|"&$B$10,Perf_data!$I$5:$I$76,0)),"") -> 272.1 | F16: =IFERROR(INDEX(Perf_data!$H$5:$H$76,MATCH($B$9&"|"&$A16&"|"&$B$10,Perf_data!$I$5:$I$76,0)),"") -> 2.1979419
A17: =IFERROR(IF(INDEX(Lists!$C$6:$Z$6,MATCH($B$9,Lists!$C$1:$Z$1,0))=0,"",INDEX(Lists!$C$6:$Z$6,MATCH($B$9,Lists!$C$1:$Z$1,0))),"") | B17: =IFERROR(INDEX(Perf_data!$D$5:$D$76,MATCH($B$9&"|"&$A17&"|"&$B$10,Perf_data!$I$5:$I$76,0)),"") | C17: =IFERROR(INDEX(Perf_data!$E$5:$E$76,MATCH($B$9&"|"&$A17&"|"&$B$10,Perf_data!$I$5:$I$76,0)),"") | D17: =IFERROR(INDEX(Perf_data!$F$5:$F$76,MATCH($B$9&"|"&$A17&"|"&$B$10,Perf_data!$I$5:$I$76,0)),"") | E17: =IFERROR(INDEX(Perf_data!$G$5:$G$76,MATCH($B$9&"|"&$A17&"|"&$B$10,Perf_data!$I$5:$I$76,0)),"") | F17: =IFERROR(INDEX(Perf_data!$H$5:$H$76,MATCH($B$9&"|"&$A17&"|"&$B$10,Perf_data!$I$5:$I$76,0)),"")
A18: =IFERROR(IF(INDEX(Lists!$C$7:$Z$7,MATCH($B$9,Lists!$C$1:$Z$1,0))=0,"",INDEX(Lists!$C$7:$Z$7,MATCH($B$9,Lists!$C$1:$Z$1,0))),"") | B18: =IFERROR(INDEX(Perf_data!$D$5:$D$76,MATCH($B$9&"|"&$A18&"|"&$B$10,Perf_data!$I$5:$I$76,0)),"") | C18: =IFERROR(INDEX(Perf_data!$E$5:$E$76,MATCH($B$9&"|"&$A18&"|"&$B$10,Perf_data!$I$5:$I$76,0)),"") | D18: =IFERROR(INDEX(Perf_data!$F$5:$F$76,MATCH($B$9&"|"&$A18&"|"&$B$10,Perf_data!$I$5:$I$76,0)),"") | E18: =IFERROR(INDEX(Perf_data!$G$5:$G$76,MATCH($B$9&"|"&$A18&"|"&$B$10,Perf_data!$I$5:$I$76,0)),"") | F18: =IFERROR(INDEX(Perf_data!$H$5:$H$76,MATCH($B$9&"|"&$A18&"|"&$B$10,Perf_data!$I$5:$I$76,0)),"")
A19: =IFERROR(IF(INDEX(Lists!$C$8:$Z$8,MATCH($B$9,Lists!$C$1:$Z$1,0))=0,"",INDEX(Lists!$C$8:$Z$8,MATCH($B$9,Lists!$C$1:$Z$1,0))),"") | B19: =IFERROR(INDEX(Perf_data!$D$5:$D$76,MATCH($B$9&"|"&$A19&"|"&$B$10,Perf_data!$I$5:$I$76,0)),"") | C19: =IFERROR(INDEX(Perf_data!$E$5:$E$76,MATCH($B$9&"|"&$A19&"|"&$B$10,Perf_data!$I$5:$I$76,0)),"") | D19: =IFERROR(INDEX(Perf_data!$F$5:$F$76,MATCH($B$9&"|"&$A19&"|"&$B$10,Perf_data!$I$5:$I$76,0)),"") | E19: =IFERROR(INDEX(Perf_data!$G$5:$G$76,MATCH($B$9&"|"&$A19&"|"&$B$10,Perf_data!$I$5:$I$76,0)),"") | F19: =IFERROR(INDEX(Perf_data!$H$5:$H$76,MATCH($B$9&"|"&$A19&"|"&$B$10,Perf_data!$I$5:$I$76,0)),"")
A20: =IFERROR(IF(INDEX(Lists!$C$9:$Z$9,MATCH($B$9,Lists!$C$1:$Z$1,0))=0,"",INDEX(Lists!$C$9:$Z$9,MATCH($B$9,Lists!$C$1:$Z$1,0))),"") | B20: =IFERROR(INDEX(Perf_data!$D$5:$D$76,MATCH($B$9&"|"&$A20&"|"&$B$10,Perf_data!$I$5:$I$76,0)),"") | C20: =IFERROR(INDEX(Perf_data!$E$5:$E$76,MATCH($B$9&"|"&$A20&"|"&$B$10,Perf_data!$I$5:$I$76,0)),"") | D20: =IFERROR(INDEX(Perf_data!$F$5:$F$76,MATCH($B$9&"|"&$A20&"|"&$B$10,Perf_data!$I$5:$I$76,0)),"") | E20: =IFERROR(INDEX(Perf_data!$G$5:$G$76,MATCH($B$9&"|"&$A20&"|"&$B$10,Perf_data!$I$5:$I$76,0)),"") | F20: =IFERROR(INDEX(Perf_data!$H$5:$H$76,MATCH($B$9&"|"&$A20&"|"&$B$10,Perf_data!$I$5:$I$76,0)),"")

Sheet Backtest
A1: Back-test: 8 quarters, no look-ahead
A2: Each quarter forecast only from snapshots and outcomes known before it began. Rolling 4-quarter training window.
A4: quarter | B4: actual | C4: commit | D4: stage_weighted | E4: cohort_age | F4: simulation | G4: ensemble | H4: final | I4: final_p10 | J4: final_p90
A5: Q1 FY25 | B5: 12.484 | C5: 11.65 | D5: 14.501311 | E5: 15.243545 | F5: 14.2112 | G5: 14.652019 | H5: 12.335685 | I5: 8.6442619 | J5: 15.209743
A6: Q2 FY25 | B6: 9.6592 | C6: 15.52 | D6: 10.660982 | E6: 11.145685 | F6: 11.249203 | G6: 11.018623 | H6: 9.1233893 | I6: 6.3932377 | J6: 11.249023
A7: Q3 FY25 | B7: 7.1735 | C7: 7.61 | D7: 8.1074846 | E7: 9.5809896 | F7: 9.0867316 | G7: 8.9250686 | H7: 6.9381731 | I7: 4.861942 | J7: 8.5546793
A8: Q4 FY25 | B8: 9.6828 | C8: 10.09 | D8: 9.7130801 | E8: 9.893921 | F8: 10.394393 | G8: 10.000465 | H8: 8.4780006 | I8: 5.94098 | J8: 10.453267
A9: Q1 FY26 | B9: 13.233 | C9: 15.74 | D9: 11.480431 | E9: 11.770101 | F9: 12.551043 | G9: 11.933858 | H9: 10.279765 | I9: 7.2035706 | J9: 12.674819
A10: Q2 FY26 | B10: 11.5192 | C10: 15.87 | D10: 13.204561 | E10: 14.436646 | F10: 14.536 | G10: 14.059069 | H10: 12.563581 | I10: 8.8039605 | J10: 15.490736
A11: Q3 FY26 | B11: 7.6966 | C11: 10.72 | D11: 12.228594 | E11: 12.721327 | F11: 12.014201 | G11: 12.321374 | H11: 11.505164 | I11: 8.0622724 | J11: 14.185721
A12: Q4 FY26 | B12: 8.5511 | C12: 11.93 | D12: 11.120202 | E12: 11.158666 | F12: 11.058366 | G12: 11.112411 | H12: 10.393207 | I12: 7.2830654 | J12: 12.814692
A14: Method | B14: Quarters | C14: MAPE | D14: Bias (mean error) | E14: MAPE last 4 | F14: Max miss
A15: Rep commit (baseline) | B15: 8 | C15: =SUMPRODUCT(ABS(C5:C12-$B$5:$B$12)/$B$5:$B$12)/8 -> 0.26644777 | D15: =SUMPRODUCT((C5:C12-$B$5:$B$12)/$B$5:$B$12)/8 -> 0.24974639 | E15: =SUMPRODUCT(ABS(C9:C12-$B$9:$B$12)/$B$9:$B$12)/4 -> 0.33877885 | F15: =SUMPRODUCT(MAX(ABS(C5:C12-$B$5:$B$12)/$B$5:$B$12)) -> 0.60675832
A16: Stage-weighted | B16: 8 | C16: =SUMPRODUCT(ABS(D5:D12-$B$5:$B$12)/$B$5:$B$12)/8 -> 0.19583136 | D16: =SUMPRODUCT((D5:D12-$B$5:$B$12)/$B$5:$B$12)/8 -> 0.16272153 | E16: =SUMPRODUCT(ABS(D9:D12-$B$9:$B$12)/$B$9:$B$12)/4 -> 0.29200497 | F16: =SUMPRODUCT(MAX(ABS(D5:D12-$B$5:$B$12)/$B$5:$B$12)) -> 0.58883066
A17: Cohort-age conversion | B17: 8 | C17: =SUMPRODUCT(ABS(E5:E12-$B$5:$B$12)/$B$5:$B$12)/8 -> 0.2567449 | D17: =SUMPRODUCT((E5:E12-$B$5:$B$12)/$B$5:$B$12)/8 -> 0.22910757 | E17: =SUMPRODUCT(ABS(E9:E12-$B$9:$B$12)/$B$9:$B$12)/4 -> 0.33040173 | F17: =SUMPRODUCT(MAX(ABS(E5:E12-$B$5:$B$12)/$B$5:$B$12)) -> 0.65285026
A18: Logistic simulation | B18: 8 | C18: =SUMPRODUCT(ABS(F5:F12-$B$5:$B$12)/$B$5:$B$12)/8 -> 0.22634682 | D18: =SUMPRODUCT((F5:F12-$B$5:$B$12)/$B$5:$B$12)/8 -> 0.21346317 | E18: =SUMPRODUCT(ABS(F9:F12-$B$9:$B$12)/$B$9:$B$12)/4 -> 0.29190316 | F18: =SUMPRODUCT(MAX(ABS(F5:F12-$B$5:$B$12)/$B$5:$B$12)) -> 0.56097511
A19: Ensemble of 3 | B19: 8 | C19: =SUMPRODUCT(ABS(G5:G12-$B$5:$B$12)/$B$5:$B$12)/8 -> 0.22630769 | D19: =SUMPRODUCT((G5:G12-$B$5:$B$12)/$B$5:$B$12)/8 -> 0.20176409 | E19: =SUMPRODUCT(ABS(G9:G12-$B$9:$B$12)/$B$9:$B$12)/4 -> 0.30476995 | F19: =SUMPRODUCT(MAX(ABS(G5:G12-$B$5:$B$12)/$B$5:$B$12)) -> 0.60088534
A20: Final: stage-weighted, calibrated | B20: 8 | C20: =SUMPRODUCT(ABS(H5:H12-$B$5:$B$12)/$B$5:$B$12)/8 -> 0.15608509 | D20: =SUMPRODUCT((H5:H12-$B$5:$B$12)/$B$5:$B$12)/8 -> 0.044146143 | E20: =SUMPRODUCT(ABS(H9:H12-$B$9:$B$12)/$B$9:$B$12)/4 -> 0.25602424 | F20: =SUMPRODUCT(MAX(ABS(H5:H12-$B$5:$B$12)/$B$5:$B$12)) -> 0.49483722
A22: p10–p90 coverage of final band | C22: =SUMPRODUCT((B5:B12>=I5:I12)*(B5:B12<=J5:J12))/8 -> 0.75
A24: FY26 rep commit MAPE | C24: =SUMPRODUCT(ABS(C9:C12-B9:B12)/B9:B12)/4 -> 0.33877885
A26: Note: the calibration step (multiply by the median actual÷forecast ratio of the previous 4 quarters) was chosen on this back-test, so its 15.6% error is slightly optimistic. The hold-out quarter is the honest test.

Sheet Holdout
A1: Q1 FY27 hold-out forecast (LOCKED)
A2: Locked 2026-09-23T11:08:13.128380Z · SHA-256 ba5b63adaffbe366041170dd6ba1df17983e5cd0fdb9bedfeac0f622fd54b6b9
A4: Method | B4: Stage-weighted conversion (stage x close-date bucket), rolling 4 quarters, walk-forward bias calibration
A5: p10 (₹ cr) | B5: 6.11
A6: p50 (₹ cr) | B6: 8.71
A7: p90 (₹ cr) | B7: 10.74
A9: Raw stage-weighted (₹ cr) | B9: 10.617
A10: Calibration factor (median actual ÷ forecast, last 4 quarters) | B10: 0.8207
A12: Cross-checks
A13: Cohort-age method | B13: 12.65
A14: Logistic simulation (expected) | B14: 10.85
A15: Simulation p10 | B15: 8.17
A16: Simulation p90 | B16: 13.48
A17: Rep commit, month 1 | B17: 9.06
A18: Quarterly quota | B18: 17.15
A20: Why the forecast is below the rep commit
A21: Conversion of open pipeline has fallen every year; uncalibrated methods over-forecast by 16–35% in the back-test. The calibration factor corrects that bias using only past quarters. 57% of snapshot value carries at least one hygiene flag (Hygiene sheet).
A25: Snapshot 1 Apr 2026: value by stage and forecast category (₹ cr)
A26: stage | B26: Best Case | C26: Commit | D26: Pipeline | E26: Pipeline - future quarter
A27: 1-Qualify | B27: 0 | C27: 0 | D27: 17.93 | E27: 16.04
A28: 2-Solution Design | B28: 0 | C28: 0 | D28: 26.01 | E28: 7.9
A29: 3-Proof of Value | B29: 8.19 | C29: 0 | D29: 8.48 | E29: 3.98
A30: 4-Proposal | B30: 6.19 | C30: 11.52 | D30: 0 | E30: 6.7
A31: 5-Negotiation & Procurement | B31: 0 | C31: 9.72 | D31: 0 | E31: 1.92

Sheet Hygiene
A1: Pipeline hygiene rules
A2: Stage exit criteria, ageing limits, slippage and single-thread flags; applied to the 1 Apr 2026 snapshot
A4: Stage | B4: Ageing limit (days) | C4: Exit criteria (to move to next stage) | D4: Median days (won FY25–26) | E4: 75th pct days
A5: 1-Qualify | B5: 75 | C5: Pain and asset scope confirmed; economic buyer named; budget route known | D5: 44 | E5: 73
A6: 2-Solution Design | B6: 65 | C6: ≥3 contacts incl. finance or procurement; security requirements captured; success criteria drafted | D6: 37.5 | E6: 66.25
A7: 3-Proof of Value | B7: 65 | C7: Paid pilot signed with written success criteria and conversion price | D7: 32.5 | E7: 67.25
A8: 4-Proposal | B8: 60 | C8: Quantified business case using buyer numbers; finance contact engaged; mutual action plan agreed | D8: 33.5 | E8: 62.5
A9: 5-Negotiation & Procurement | B9: 80 | C9: Paper process mapped; legal/security cleared; signature date confirmed by economic buyer | D9: 51 | E9: 82.5
A11: Flag | B11: Rule | D11: Deals flagged | E11: Value (₹ cr)
A12: stale_date | B12: Expected close date already past | D12: 27 | E12: 12.7795
A13: slipped2 | B13: Close date pushed 2+ times | D13: 18 | E13: 8.2327
A14: aged | B14: Longer in stage than the ageing limit | D14: 86 | E14: 41.0641
A15: single_thread | B15: Stage 3+ with only one buyer contact | D15: 74 | E15: 36.321
A16: no_activity_90d | B16: No activity for 90 days | D16: 11 | E16: 6.032
A17: commit_not_stage5 | B17: In Commit but not at stage 5 | D17: 27 | E17: 11.5246
A18: any_flag | B18: Any flag | D18: 148 | E18: 70.6603
A20: Snapshot value (₹ cr) | E20: 124.5977
A21: Share of value with any flag | E21: =E18/E20 -> 0.56710758
A22: In-quarter pipeline, all / clean (no flags) (₹ cr) | D22: 77.9702 | E22: 34.0898
A23: Clean in-quarter coverage (× quota ₹17.15 cr) | E23: =E22/17.15 -> 1.9877434
A25: Top 60 flagged deals by value (for Monday inspection)
A26: opp_id | B26: stage | C26: forecast_category | D26: val_cr | E26: expected_close_date | F26: pushes | G26: days_in_stage | H26: contacts | I26: owner_ae_id | J26: f_stale_date | K26: f_slipped2 | L26: f_aged | M26: f_single_thread | N26: f_no_activity_90d | O26: f_commit_not_stage5
A27: OPP-113578 | B27: 4-Proposal | C27: Best Case | D27: 1.8842 | E27: 46133 | F27: 0 | G27: 20 | H27: 1 | I27: AE071 | J27: =FALSE() -> FALSE | K27: =FALSE() -> FALSE | L27: =FALSE() -> FALSE | M27: =TRUE() -> TRUE | N27: =FALSE() -> FALSE | O27: =FALSE() -> FALSE
A28: OPP-111775 | B28: 5-Negotiation & Procurement | C28: Commit | D28: 1.171 | E28: 46111 | F28: 0 | G28: 22 | H28: 1 | I28: AE043 | J28: =TRUE() -> TRUE | K28: =FALSE() -> FALSE | L28: =FALSE() -> FALSE | M28: =TRUE() -> TRUE | N28: =FALSE() -> FALSE | O28: =FALSE() -> FALSE
A29: OPP-111702 | B29: 3-Proof of Value | C29: Best Case | D29: 1.156 | E29: 46200 | F29: 1 | G29: 203 | H29: 5 | I29: AE051 | J29: =FALSE() -> FALSE | K29: =FALSE() -> FALSE | L29: =TRUE() -> TRUE | M29: =FALSE() -> FALSE | N29: =FALSE() -> FALSE | O29: =FALSE() -> FALSE
A30: OPP-113847 | B30: 3-Proof of Value | C30: Pipeline - future quarter | D30: 1.1036 | E30: 46225 | F30: 0 | G30: 6 | H30: 1 | I30: AE107 | J30: =FALSE() -> FALSE | K30: =FALSE() -> FALSE | L30: =FALSE() -> FALSE | M30: =TRUE() -> TRUE | N30: =FALSE() -> FALSE | O30: =FALSE() -> FALSE
A31: OPP-113065 | B31: 3-Proof of Value | C31: Pipeline | D31: 0.9533 | E31: 46100 | F31: 0 | G31: 13 | H31: 1 | I31: AE053 | J31: =TRUE() -> TRUE | K31: =FALSE() -> FALSE | L31: =FALSE() -> FALSE | M31: =TRUE() -> TRUE | N31: =FALSE() -> FALSE | O31: =FALSE() -> FALSE
A32: OPP-112470 | B32: 4-Proposal | C32: Pipeline - future quarter | D32: 0.9503 | E32: 46206 | F32: 1 | G32: 105 | H32: 4 | I32: AE026 | J32: =FALSE() -> FALSE | K32: =FALSE() -> FALSE | L32: =TRUE() -> TRUE | M32: =FALSE() -> FALSE | N32: =FALSE() -> FALSE | O32: =FALSE() -> FALSE
A33: OPP-112131 | B33: 4-Proposal | C33: Commit | D33: 0.9327 | E33: 46152 | F33: 1 | G33: 12 | H33: 3 | I33: AE041 | J33: =FALSE() -> FALSE | K33: =FALSE() -> FALSE | L33: =FALSE() -> FALSE | M33: =FALSE() -> FALSE | N33: =FALSE() -> FALSE | O33: =TRUE() -> TRUE
A34: OPP-111346 | B34: 3-Proof of Value | C34: Pipeline - future quarter | D34: 0.9293 | E34: 46207 | F34: 1 | G34: 151 | H34: 1 | I34: AE005 | J34: =FALSE() -> FALSE | K34: =FALSE() -> FALSE | L34: =TRUE() -> TRUE | M34: =TRUE() -> TRUE | N34: =FALSE() -> FALSE | O34: =FALSE() -> FALSE
A35: OPP-111874 | B35: 5-Negotiation & Procurement | C35: Commit | D35: 0.9258 | E35: 46142 | F35: 1 | G35: 13 | H35: 1 | I35: AE092 | J35: =FALSE() -> FALSE | K35: =FALSE() -> FALSE | L35: =FALSE() -> FALSE | M35: =TRUE() -> TRUE | N35: =FALSE() -> FALSE | O35: =FALSE() -> FALSE
A36: OPP-109713 | B36: 4-Proposal | C36: Commit | D36: 0.9053 | E36: 46027 | F36: 2 | G36: 167 | H36: 1 | I36: AE083 | J36: =TRUE() -> TRUE | K36: =TRUE() -> TRUE | L36: =TRUE() -> TRUE | M36: =TRUE() -> TRUE | N36: =TRUE() -> TRUE | O36: =TRUE() -> TRUE
A37: OPP-112478 | B37: 5-Negotiation & Procurement | C37: Commit | D37: 0.8245 | E37: 46167 | F37: 0 | G37: 34 | H37: 1 | I37: AE043 | J37: =FALSE() -> FALSE | K37: =FALSE() -> FALSE | L37: =FALSE() -> FALSE | M37: =TRUE() -> TRUE | N37: =FALSE() -> FALSE | O37: =FALSE() -> FALSE
A38: OPP-109718 | B38: 4-Proposal | C38: Pipeline - future quarter | D38: 0.8117 | E38: 45858 | F38: 1 | G38: 325 | H38: 1 | I38: AE078 | J38: =TRUE() -> TRUE | K38: =FALSE() -> FALSE | L38: =TRUE() -> TRUE | M38: =TRUE() -> TRUE | N38: =TRUE() -> TRUE | O38: =FALSE() -> FALSE
A39: OPP-113432 | B39: 1-Qualify | C39: Pipeline | D39: 0.8095 | E39: 46157 | F39: 0 | G39: 110 | H39: 1 | I39: AE031 | J39: =FALSE() -> FALSE | K39: =FALSE() -> FALSE | L39: =TRUE() -> TRUE | M39: =FALSE() -> FALSE | N39: =FALSE() -> FALSE | O39: =FALSE() -> FALSE
A40: OPP-112907 | B40: 4-Proposal | C40: Commit | D40: 0.8039 | E40: 46189 | F40: 0 | G40: 18 | H40: 1 | I40: AE007 | J40: =FALSE() -> FALSE | K40: =FALSE() -> FALSE | L40: =FALSE() -> FALSE | M40: =TRUE() -> TRUE | N40: =FALSE() -> FALSE | O40: =TRUE() -> TRUE
A41: OPP-113079 | B41: 2-Solution Design | C41: Pipeline | D41: 0.7963 | E41: 46160 | F41: 1 | G41: 113 | H41: 1 | I41: AE005 | J41: =FALSE() -> FALSE | K41: =FALSE() -> FALSE | L41: =TRUE() -> TRUE | M41: =FALSE() -> FALSE | N41: =FALSE() -> FALSE | O41: =FALSE() -> FALSE
A42: OPP-113173 | B42: 4-Proposal | C42: Pipeline - future quarter | D42: 0.7917 | E42: 46244 | F42: 0 | G42: 39 | H42: 1 | I42: AE077 | J42: =FALSE() -> FALSE | K42: =FALSE() -> FALSE | L42: =FALSE() -> FALSE | M42: =TRUE() -> TRUE | N42: =FALSE() -> FALSE | O42: =FALSE() -> FALSE
A43: OPP-110937 | B43: 3-Proof of Value | C43: Pipeline | D43: 0.7844 | E43: 46165 | F43: 1 | G43: 50 | H43: 1 | I43: AE071 | J43: =FALSE() -> FALSE | K43: =FALSE() -> FALSE | L43: =FALSE() -> FALSE | M43: =TRUE() -> TRUE | N43: =FALSE() -> FALSE | O43: =FALSE() -> FALSE
A44: OPP-113228 | B44: 2-Solution Design | C44: Pipeline | D44: 0.764 | E44: 46115 | F44: 1 | G44: 87 | H44: 1 | I44: AE027 | J44: =FALSE() -> FALSE | K44: =FALSE() -> FALSE | L44: =TRUE() -> TRUE | M44: =FALSE() -> FALSE | N44: =FALSE() -> FALSE | O44: =FALSE() -> FALSE
...

Sheet Scenarios
A1: FY27–FY29 scenarios (linked to D2 and D3 assumptions)
A2: Blue inputs; ending ARR = opening × NRR + new-logo ARR. D7 replaces this with the full integrated model.
A4: Scenario selector | B4: Base
A6: Driver | B6: Base FY27 | C6: Base FY28 | D6: Base FY29 | E6: Down FY27 | F6: Down FY28 | G6: Down FY29 | H6: Aggr FY27 | I6: Aggr FY28 | J6: Aggr FY29 | K6: Source / link
A7: Win rate on qualified deals | B7: 0.218 | C7: 0.23 | D7: 0.235 | E7: 0.17 | F7: 0.175 | G7: 0.18 | H7: 0.23 | I7: 0.25 | J7: 0.26 | K7: D1 FY26 16.9%; D2 plan mix implies 21.8% (63.5 won ÷ 291 qualified); board goal 23% by FY28
A8: Qualified opportunities (direct) | B8: 291 | C8: 330 | D8: 350 | E8: 291 | F8: 300 | G8: 310 | H8: 300 | I8: 360 | J8: 420 | K8: D2 funnel (291 for FY27); FY28–29 volumes need the capacity D7 must fund
A9: Average won deal (₹ lakh) | B9: 66.9 | C9: 70 | D9: 73 | E9: 60 | F9: 61 | G9: 62 | H9: 68 | I9: 72 | J9: 76 | K9: D2 plan mix (₹42.5 cr ÷ 63.5 deals)
A10: Partner-sourced new-logo ARR (₹ cr) | B10: 4 | C10: 9 | D10: 18 | E10: 2.6 | F10: 4 | G10: 6 | H10: 4.5 | I10: 11 | J10: 22 | K10: D2 SEA plan; D6 builds the channel
A11: Net revenue retention | B11: 1 | C11: 1.04 | D11: 1.07 | E11: 0.97 | F11: 0.99 | G11: 1.01 | H11: 1.01 | I11: 1.05 | J11: 1.08 | K11: D1 FY26 98.9%; Inject 1 retention squad; board 108% by FY29
A13: Direct new-logo ARR (₹ cr) = opps × win × deal | B13: =B8*B7*B9/100 -> 42.440022 | C13: =C8*C7*C9/100 -> 53.13 | D13: =D8*D7*D9/100 -> 60.0425 | E13: =E8*E7*E9/100 -> 29.682 | F13: =F8*F7*F9/100 -> 32.025 | G13: =G8*G7*G9/100 -> 34.596 | H13: =H8*H7*H9/100 -> 46.92 | I13: =I8*I7*I9/100 -> 64.8 | J13: =J8*J7*J9/100 -> 82.992
A14: Total new-logo ARR (₹ cr) | B14: =B13+B10 -> 46.440022 | C14: =C13+C10 -> 62.13 | D14: =D13+D10 -> 78.0425 | E14: =E13+E10 -> 32.282 | F14: =F13+F10 -> 36.025 | G14: =G13+G10 -> 40.596 | H14: =H13+H10 -> 51.42 | I14: =I13+I10 -> 75.8 | J14: =J13+J10 -> 104.992
A15: Opening ARR (₹ cr) | B15: 310 | C15: =B16 -> 356.44002 | D15: =C16 -> 432.82762 | E15: 310 | F15: =E16 -> 332.982 | G15: =F16 -> 365.67718 | H15: 310 | I15: =H16 -> 364.52 | J15: =I16 -> 458.546
A16: Ending ARR (₹ cr) | B16: =B15*B11+B14 -> 356.44002 | C16: =C15*C11+C14 -> 432.82762 | D16: =D15*D11+D14 -> 541.16806 | E16: =E15*E11+E14 -> 332.982 | F16: =F15*F11+F14 -> 365.67718 | G16: =G15*G11+G14 -> 409.92995 | H16: =H15*H11+H14 -> 364.52 | I16: =I15*I11+I14 -> 458.546 | J16: =J15*J11+J14 -> 600.22168
A17: ARR growth | B17: =B16/B15-1 -> 0.14980652 | C17: =C16/C15-1 -> 0.21430703 | D17: =D16/D15-1 -> 0.2503085 | E17: =E16/E15-1 -> 0.074135484 | F17: =F16/F15-1 -> 0.098189031 | G17: =G16/G15-1 -> 0.12101595 | H17: =H16/H15-1 -> 0.17587097 | I17: =I16/I15-1 -> 0.25794469 | J17: =J16/J15-1 -> 0.30896721
A18: Board path ending ARR (₹ cr) | B18: 356.5 | C18: 427.8 | D18: 521.9 | E18: 356.5 | F18: 427.8 | G18: 521.9 | H18: 356.5 | I18: 427.8 | J18: 521.9
A19: Gap to board path (₹ cr) | B19: =B16-B18 -> -0.059978 | C19: =C16-C18 -> 5.0276229 | D19: =D16-D18 -> 19.268056 | E19: =E16-E18 -> -23.518 | F19: =F16-F18 -> -62.12282 | G19: =G16-G18 -> -111.97005 | H19: =H16-H18 -> 8.02 | I19: =I16-I18 -> 30.746 | J19: =J16-J18 -> 78.32168
A21: Selected scenario, FY29 ending ARR (₹ cr) | B21: =IF(B4="Base",D16,IF(B4="Downside",G16,J16)) -> 541.16806
A22: Selected scenario, FY29 gap to ₹521.9 cr | B22: =B21-521.9 -> 19.268056

Sheet Governance
A1: Forecast governance
A2: Categories, weekly routine, deal inspection checklist and role views
A4: FORECAST CATEGORIES
A5: Commit | B5: Stage 5; economic buyer has confirmed the signature date; paper process mapped; ≥3 contacts; close date inside the quarter and never pushed more than once. Target conversion ≥70%.
A6: Best case | B6: Stage 4 with a quantified business case and a mutual action plan; close date inside the quarter.
A7: Pipeline | B7: Qualified (stage 2+) with a close date inside the quarter that does not meet Best-case rules.
A8: Omitted | B8: Any hygiene flag unresolved for 2 weeks, or stage 1. Excluded from coverage and forecast.
A9: WEEKLY ROUTINE
A10: Monday 10:00 | B10: Reps update stage, close date, next step and contacts; hygiene flags auto-generated (Hygiene sheet).
A11: Tuesday | B11: Manager 1:1 deal inspection on every Commit and Best-case deal using the checklist; flags resolved or deals moved to Omitted.
A12: Wednesday | B12: CRO forecast call: model p50 and p10–p90 vs manager call vs rep commit; explain any gap > 10%.
A13: Thursday | B13: CFO view: forecast range, clean coverage vs required, top-10 deals; one number submitted to finance.
A14: DEAL INSPECTION CHECKLIST
A15: 1 | B15: Who is the economic buyer and when did we last meet them?
A16: 2 | B16: Which buyer-supplied number is in the business case?
A17: 3 | B17: How many contacts, and are finance, procurement and IT security among them?
A18: 4 | B18: What is the paper process, step by step, with dates?
A19: 5 | B19: What happens if the buyer does nothing? What is the compelling event?
A20: 6 | B20: Which competitor is present and what is our counter?
A21: 7 | B21: Has the close date moved? Why?
A22: ROLE VIEWS
A23: Rep | B23: Own deals with flags, next steps, contacts gap; personal commit vs model.
A24: Manager | B24: Team Commit/Best case, flag list, conversion vs plan, deals to inspect.
A25: CRO | B25: Model p50 and range vs manager calls; coverage required vs reported by region; win rate by tier and competitor.
A26: CFO | B26: One forecast number with range; bias history; clean coverage; bookings vs plan.
